{"name": "Тест на получение ошибки при получения заказов без авторизации", "status": "passed", "description": "Проверяется, что сервер возвращает 401 и сообщение об ошибке.", "start": 1747223372564, "stop": 1747223372813, "uuid": "8a4d05b0-a03e-4696-9335-56dc603609a0", "historyId": "4a8379267525db1b6f36c5f5830ebebf", "testCaseId": "4a8379267525db1b6f36c5f5830ebebf", "fullName": "tests.test_order.TestCreateOrder#test_create_order_with_auth", "labels": [{"name": "parentSuite", "value": "tests"}, {"name": "suite", "value": "test_order"}, {"name": "subSuite", "value": "TestCreateOrder"}, {"name": "host", "value": "LAPTOP-3QFAQEQR"}, {"name": "thread", "value": "6276-MainThread"}, {"name": "framework", "value": "pytest"}, {"name": "language", "value": "cpython3"}, {"name": "package", "value": "tests.test_order"}]}